Workbook
Name ScaleROI: Summary!$B$5
Name CutROI: Summary!$B$6
Name MinSignups: Summary!$B$7

Sheet Summary
A1: Marketing ROI and Cohort Analysis
A2: Sign-ups Jan 1, 2024 to Jul 5, 2025, outcomes within 180 days · built Oct 04, 2026 14:07 by mroi v1.0.0
A4: Decision rules (change the yellow cells)
A5: Scale if 180-day ROI is at least | B5: 0.5
A6: Cut if ROI is below, with no 12-month payback | B6: 0
A7: Minimum sign-ups to judge a campaign | B7: 300
A9: Headline KPIs (measured window)
A10: Spend | B10: =Scorecard!D19
A11: Sign-ups | B11: =Scorecard!G19
A12: Customers within 180 days | B12: =Scorecard!I19
A13: Sign-up to customer conversion | B13: =Scorecard!T19
A14: Blended CAC | B14: =Scorecard!U19
A15: ROAS (180-day revenue ÷ spend) | B15: =Scorecard!W19
A16: ROI (180-day gross profit vs spend) | B16: =Scorecard!X19
A19: Campaigns
A20: Campaign | B20: Channel | C20: Spend | D20: CAC | E20: ROI | F20: Pays back within (months) | G20: Action
A21: =Scorecard!B6 | B21: =Scorecard!C6 | C21: =Scorecard!D6 | D21: =Scorecard!U6 | E21: =Scorecard!X6 | F21: =Scorecard!M6 | G21: =Scorecard!Z6
A22: =Scorecard!B7 | B22: =Scorecard!C7 | C22: =Scorecard!D7 | D22: =Scorecard!U7 | E22: =Scorecard!X7 | F22: =Scorecard!M7 | G22: =Scorecard!Z7
A23: =Scorecard!B8 | B23: =Scorecard!C8 | C23: =Scorecard!D8 | D23: =Scorecard!U8 | E23: =Scorecard!X8 | F23: =Scorecard!M8 | G23: =Scorecard!Z8
A24: =Scorecard!B9 | B24: =Scorecard!C9 | C24: =Scorecard!D9 | D24: =Scorecard!U9 | E24: =Scorecard!X9 | F24: =Scorecard!M9 | G24: =Scorecard!Z9
A25: =Scorecard!B10 | B25: =Scorecard!C10 | C25: =Scorecard!D10 | D25: =Scorecard!U10 | E25: =Scorecard!X10 | F25: =Scorecard!M10 | G25: =Scorecard!Z10
A26: =Scorecard!B11 | B26: =Scorecard!C11 | C26: =Scorecard!D11 | D26: =Scorecard!U11 | E26: =Scorecard!X11 | F26: =Scorecard!M11 | G26: =Scorecard!Z11
A27: =Scorecard!B12 | B27: =Scorecard!C12 | C27: =Scorecard!D12 | D27: =Scorecard!U12 | E27: =Scorecard!X12 | F27: =Scorecard!M12 | G27: =Scorecard!Z12
A28: =Scorecard!B13 | B28: =Scorecard!C13 | C28: =Scorecard!D13 | D28: =Scorecard!U13 | E28: =Scorecard!X13 | F28: =Scorecard!M13 | G28: =Scorecard!Z13
A29: =Scorecard!B14 | B29: =Scorecard!C14 | C29: =Scorecard!D14 | D29: =Scorecard!U14 | E29: =Scorecard!X14 | F29: =Scorecard!M14 | G29: =Scorecard!Z14
A30: =Scorecard!B15 | B30: =Scorecard!C15 | C30: =Scorecard!D15 | D30: =Scorecard!U15 | E30: =Scorecard!X15 | F30: =Scorecard!M15 | G30: =Scorecard!Z15
A31: =Scorecard!B16 | B31: =Scorecard!C16 | C31: =Scorecard!D16 | D31: =Scorecard!U16 | E31: =Scorecard!X16 | F31: =Scorecard!M16 | G31: =Scorecard!Z16
A32: =Scorecard!B17 | B32: =Scorecard!C17 | C32: =Scorecard!D17 | D32: =Scorecard!U17 | E32: =Scorecard!X17 | F32: =Scorecard!M17 | G32: =Scorecard!Z17
A33: =Scorecard!B18 | B33: =Scorecard!C18 | C33: =Scorecard!D18 | D33: =Scorecard!U18 | E33: =Scorecard!X18 | F33: =Scorecard!M18 | G33: =Scorecard!Z18
A35: Key findings and recommendation
A36: • Sign-ups from Jan 1, 2024 to Jul 5, 2025: $896K of spend brought 21,057 customers within 180 days at a blended CAC of $43, for a +1% ROI on 180-day gross profit (2.54x ROAS).
A37: • Search - Brand is the strongest campaign (+264% ROI at a $20 CAC); Display - Programmatic is the weakest (-86% ROI at a $180 CAC).
A38: • The largest budget line, Social - Lookalike Prospecting (23% of measured spend), returns -68% at 180 days.
A39: • Affiliate and Referral pay back fastest (within 60 days); Display and Paid Social do not pay back within 12 months.
A40: • 30-day conversion fell from 25.1% for the first six cohorts (Jan 2024–Jun 2024) to 23.5% for the latest six (Jun 2025–Nov 2025). Paid Social explains most of the change: its share of sign-ups went from 33% to 40% and its 30-day conversion from 17.2% to 16.4%.
A41: • Social - Short Video Test started on Sep 1, 2025, so it's too new to judge. Its first sign-ups reach 180 days of history on Feb 27, 2026.
A42: • Recommendation: halve the 4 campaigns marked 'Cut or rework' and grow the 4 marked 'Scale' by 50%. If CAC holds, annual spend changes by -$74K and 180-day gross profit after spend improves by $207K a year. Test the increases in steps, because CAC usually rises as campaigns scale.
A44: Findings are written by Python for this run; the tables above update when you change the decision rules.

Sheet Scorecard
A1: Campaign scorecard
A2: Sign-ups (and the spend that bought them) from Jan 1, 2024 to Jul 5, 2025, with every outcome counted within 180 days of sign-up.
A4: From SQL | O4: Calculated in Excel
A5: Campaign ID | B5: Campaign | C5: Channel | D5: Spend | E5: Impressions | F5: Clicks | G5: Sign-ups | H5: Customers in 7 days | I5: Customers in 180 days | J5: Orders in 180 days | K5: Revenue in 180 days | L5: Gross profit in 180 days | M5: Pays back within (months) | N5: Spend, last 12 months (live campaigns) | O5: CTR | P5: CPC | Q5: Sign-up rate | R5: Cost per sign-up | S5: 7-day conversion | T5: 180-day conversion | U5: CAC | V5: Gross profit per customer | W5: ROAS | X5: ROI | Y5: LTV:CAC | Z5: Action
A6: C01 | B6: Search - Brand | C6: Paid Search | D6: 47617.64 | E6: 427582 | F6: 33791 | G6: 6122 | H6: 1618 | I6: 2328 | J6: 5186 | K6: 367848.37 | L6: 173564.59 | M6: 1 | N6: 33707.02 | O6: =IF(E6=0,"",F6/E6) | P6: =IF(F6=0,"",D6/F6) | Q6: =IF(F6=0,"",G6/F6) | R6: =IF(G6=0,"",D6/G6) | S6: =IF(G6=0,"",H6/G6) | T6: =IF(G6=0,"",I6/G6) | U6: =IF(I6=0,"",D6/I6) | V6: =IF(I6=0,"",L6/I6) | W6: =IF(D6=0,"",K6/D6) | X6: =IF(D6=0,"",(L6-D6)/D6) | Y6: =IF(OR(U6="",V6=""),"",V6/U6) | Z6: =IF(OR(G6<MinSignups,X6=""),"Too early to judge",IF(X6>=ScaleROI,"Scale",IF(OR(X6>=CutROI,ISNUMBER(M6)),"Optimize","Cut or rework")))
A7: C09 | B7: Affiliate - Content Partners | C7: Affiliate | D7: 45356.01 | E7: 2287212 | F7: 45533 | G7: 5369 | H7: 857 | I7: 1620 | J7: 3235 | K7: 234282.03 | L7: 109144.98 | M7: 1 | N7: 35655.51 | O7: =IF(E7=0,"",F7/E7) | P7: =IF(F7=0,"",D7/F7) | Q7: =IF(F7=0,"",G7/F7) | R7: =IF(G7=0,"",D7/G7) | S7: =IF(G7=0,"",H7/G7) | T7: =IF(G7=0,"",I7/G7) | U7: =IF(I7=0,"",D7/I7) | V7: =IF(I7=0,"",L7/I7) | W7: =IF(D7=0,"",K7/D7) | X7: =IF(D7=0,"",(L7-D7)/D7) | Y7: =IF(OR(U7="",V7=""),"",V7/U7) | Z7: =IF(OR(G7<MinSignups,X7=""),"Too early to judge",IF(X7>=ScaleROI,"Scale",IF(OR(X7>=CutROI,ISNUMBER(M7)),"Optimize","Cut or rework")))
A8: C05 | B8: Social - Retargeting | C8: Paid Social | D8: 58224.23 | E8: 3589056 | F8: 53184 | G8: 7442 | H8: 1525 | I8: 2345 | J8: 4524 | K8: 298477.27 | L8: 131634.69 | M8: 1 | N8: 41836.29 | O8: =IF(E8=0,"",F8/E8) | P8: =IF(F8=0,"",D8/F8) | Q8: =IF(F8=0,"",G8/F8) | R8: =IF(G8=0,"",D8/G8) | S8: =IF(G8=0,"",H8/G8) | T8: =IF(G8=0,"",I8/G8) | U8: =IF(I8=0,"",D8/I8) | V8: =IF(I8=0,"",L8/I8) | W8: =IF(D8=0,"",K8/D8) | X8: =IF(D8=0,"",(L8-D8)/D8) | Y8: =IF(OR(U8="",V8=""),"",V8/U8) | Z8: =IF(OR(G8<MinSignups,X8=""),"Too early to judge",IF(X8>=ScaleROI,"Scale",IF(OR(X8>=CutROI,ISNUMBER(M8)),"Optimize","Cut or rework")))
A9: C11 | B9: Referral - Give $20 Get $20 | C9: Referral | D9: 42938.33 | E9: 143186 | F9: 14287 | G9: 3529 | H9: 808 | I9: 1061 | J9: 2497 | K9: 172636.24 | L9: 78048.33 | M9: 2 | N9: 30887.57 | O9: =IF(E9=0,"",F9/E9) | P9: =IF(F9=0,"",D9/F9) | Q9: =IF(F9=0,"",G9/F9) | R9: =IF(G9=0,"",D9/G9) | S9: =IF(G9=0,"",H9/G9) | T9: =IF(G9=0,"",I9/G9) | U9: =IF(I9=0,"",D9/I9) | V9: =IF(I9=0,"",L9/I9) | W9: =IF(D9=0,"",K9/D9) | X9: =IF(D9=0,"",(L9-D9)/D9) | Y9: =IF(OR(U9="",V9=""),"",V9/U9) | Z9: =IF(OR(G9<MinSignups,X9=""),"Too early to judge",IF(X9>=ScaleROI,"Scale",IF(OR(X9>=CutROI,ISNUMBER(M9)),"Optimize","Cut or rework")))
A10: C10 | B10: Email - Partner Newsletters | C10: Email | D10: 31833.21 | E10: 1186309 | F10: 35451 | G10: 3588 | H10: 517 | I10: 859 | J10: 1486 | K10: 91612.67 | L10: 39874.85 | M10: 3 | N10: 22843.89 | O10: =IF(E10=0,"",F10/E10) | P10: =IF(F10=0,"",D10/F10) | Q10: =IF(F10=0,"",G10/F10) | R10: =IF(G10=0,"",D10/G10) | S10: =IF(G10=0,"",H10/G10) | T10: =IF(G10=0,"",I10/G10) | U10: =IF(I10=0,"",D10/I10) | V10: =IF(I10=0,"",L10/I10) | W10: =IF(D10=0,"",K10/D10) | X10: =IF(D10=0,"",(L10-D10)/D10) | Y10: =IF(OR(U10="",V10=""),"",V10/U10) | Z10: =IF(OR(G10<MinSignups,X10=""),"Too early to judge",IF(X10>=ScaleROI,"Scale",IF(OR(X10>=CutROI,ISNUMBER(M10)),"Optimize","Cut or rework")))
A11: C08 | B11: Affiliate - Coupon Sites | C11: Affiliate | D11: 64310.11 | E11: 4670973 | F11: 92160 | G11: 13862 | H11: 4665 | I11: 5630 | J11: 8592 | K11: 388066.32 | L11: 74907.32 | M11: 4 | N11: 46031.81 | O11: =IF(E11=0,"",F11/E11) | P11: =IF(F11=0,"",D11/F11) | Q11: =IF(F11=0,"",G11/F11) | R11: =IF(G11=0,"",D11/G11) | S11: =IF(G11=0,"",H11/G11) | T11: =IF(G11=0,"",I11/G11) | U11: =IF(I11=0,"",D11/I11) | V11: =IF(I11=0,"",L11/I11) | W11: =IF(D11=0,"",K11/D11) | X11: =IF(D11=0,"",(L11-D11)/D11) | Y11: =IF(OR(U11="",V11=""),"",V11/U11) | Z11: =IF(OR(G11<MinSignups,X11=""),"Too early to judge",IF(X11>=ScaleROI,"Scale",IF(OR(X11>=CutROI,ISNUMBER(M11)),"Optimize","Cut or rework")))
A12: C12 | B12: Video - Product Demos | C12: Video | D12: 58552.13 | E12: 8148970 | F12: 65053 | G12: 5206 | H12: 383 | I12: 1042 | J12: 1760 | K12: 136162.2 | L12: 58837.6 | M12: 6 | N12: 56732.32 | O12: =IF(E12=0,"",F12/E12) | P12: =IF(F12=0,"",D12/F12) | Q12: =IF(F12=0,"",G12/F12) | R12: =IF(G12=0,"",D12/G12) | S12: =IF(G12=0,"",H12/G12) | T12: =IF(G12=0,"",I12/G12) | U12: =IF(I12=0,"",D12/I12) | V12: =IF(I12=0,"",L12/I12) | W12: =IF(D12=0,"",K12/D12) | X12: =IF(D12=0,"",(L12-D12)/D12) | Y12: =IF(OR(U12="",V12=""),"",V12/U12) | Z12: =IF(OR(G12<MinSignups,X12=""),"Too early to judge",IF(X12>=ScaleROI,"Scale",IF(OR(X12>=CutROI,ISNUMBER(M12)),"Optimize","Cut or rework")))
A13: C02 | B13: Search - Generic | C13: Paid Search | D13: 137682.78 | E13: 1923295 | F13: 76181 | G13: 9163 | H13: 1104 | I13: 2527 | J13: 4485 | K13: 286196.69 | L13: 124717.57 | M13: 11 | N13: 98417.18 | O13: =IF(E13=0,"",F13/E13) | P13: =IF(F13=0,"",D13/F13) | Q13: =IF(F13=0,"",G13/F13) | R13: =IF(G13=0,"",D13/G13) | S13: =IF(G13=0,"",H13/G13) | T13: =IF(G13=0,"",I13/G13) | U13: =IF(I13=0,"",D13/I13) | V13: =IF(I13=0,"",L13/I13) | W13: =IF(D13=0,"",K13/D13) | X13: =IF(D13=0,"",(L13-D13)/D13) | Y13: =IF(OR(U13="",V13=""),"",V13/U13) | Z13: =IF(OR(G13<MinSignups,X13=""),"Too early to judge",IF(X13>=ScaleROI,"Scale",IF(OR(X13>=CutROI,ISNUMBER(M13)),"Optimize","Cut or rework")))
A14: C06 | B14: Social - Influencer Holiday | C14: Paid Social | D14: 61065.58 | E14: 3890117 | F14: 38248 | G14: 3846 | H14: 397 | I14: 774 | J14: 1153 | K14: 82421.76 | L14: 31732.05 | M14: Not yet | N14: 64435.94 | O14: =IF(E14=0,"",F14/E14) | P14: =IF(F14=0,"",D14/F14) | Q14: =IF(F14=0,"",G14/F14) | R14: =IF(G14=0,"",D14/G14) | S14: =IF(G14=0,"",H14/G14) | T14: =IF(G14=0,"",I14/G14) | U14: =IF(I14=0,"",D14/I14) | V14: =IF(I14=0,"",L14/I14) | W14: =IF(D14=0,"",K14/D14) | X14: =IF(D14=0,"",(L14-D14)/D14) | Y14: =IF(OR(U14="",V14=""),"",V14/U14) | Z14: =IF(OR(G14<MinSignups,X14=""),"Too early to judge",IF(X14>=ScaleROI,"Scale",IF(OR(X14>=CutROI,ISNUMBER(M14)),"Optimize","Cut or rework")))
A15: C04 | B15: Social - Lookalike Prospecting | C15: Paid Social | D15: 203882.94 | E15: 15536389 | F15: 185205 | G15: 16807 | H15: 588 | I15: 2144 | J15: 2982 | K15: 164916.64 | L15: 64292.56 | M15: Not yet | N15: 160869.28 | O15: =IF(E15=0,"",F15/E15) | P15: =IF(F15=0,"",D15/F15) | Q15: =IF(F15=0,"",G15/F15) | R15: =IF(G15=0,"",D15/G15) | S15: =IF(G15=0,"",H15/G15) | T15: =IF(G15=0,"",I15/G15) | U15: =IF(I15=0,"",D15/I15) | V15: =IF(I15=0,"",L15/I15) | W15: =IF(D15=0,"",K15/D15) | X15: =IF(D15=0,"",(L15-D15)/D15) | Y15: =IF(OR(U15="",V15=""),"",V15/U15) | Z15: =IF(OR(G15<MinSignups,X15=""),"Too early to judge",IF(X15>=ScaleROI,"Scale",IF(OR(X15>=CutROI,ISNUMBER(M15)),"Optimize","Cut or rework")))
A16: C03 | B16: Search - Competitor | C16: Paid Search | D16: 55218.58 | E16: 541643 | F16: 16218 | G16: 1353 | H16: 90 | I16: 229 | J16: 362 | K16: 22997.81 | L16: 9778.36 | M16: Not yet | N16: 0 | O16: =IF(E16=0,"",F16/E16) | P16: =IF(F16=0,"",D16/F16) | Q16: =IF(F16=0,"",G16/F16) | R16: =IF(G16=0,"",D16/G16) | S16: =IF(G16=0,"",H16/G16) | T16: =IF(G16=0,"",I16/G16) | U16: =IF(I16=0,"",D16/I16) | V16: =IF(I16=0,"",L16/I16) | W16: =IF(D16=0,"",K16/D16) | X16: =IF(D16=0,"",(L16-D16)/D16) | Y16: =IF(OR(U16="",V16=""),"",V16/U16) | Z16: =IF(OR(G16<MinSignups,X16=""),"Too early to judge",IF(X16>=ScaleROI,"Scale",IF(OR(X16>=CutROI,ISNUMBER(M16)),"Optimize","Cut or rework")))
A17: C07 | B17: Display - Programmatic | C17: Display | D17: 89460.18 | E17: 50516512 | F17: 200007 | G17: 5002 | H17: 110 | I17: 498 | J17: 658 | K17: 32609.25 | L17: 12600.12 | M17: Not yet | N17: 64438.87 | O17: =IF(E17=0,"",F17/E17) | P17: =IF(F17=0,"",D17/F17) | Q17: =IF(F17=0,"",G17/F17) | R17: =IF(G17=0,"",D17/G17) | S17: =IF(G17=0,"",H17/G17) | T17: =IF(G17=0,"",I17/G17) | U17: =IF(I17=0,"",D17/I17) | V17: =IF(I17=0,"",L17/I17) | W17: =IF(D17=0,"",K17/D17) | X17: =IF(D17=0,"",(L17-D17)/D17) | Y17: =IF(OR(U17="",V17=""),"",V17/U17) | Z17: =IF(OR(G17<MinSignups,X17=""),"Too early to judge",IF(X17>=ScaleROI,"Scale",IF(OR(X17>=CutROI,ISNUMBER(M17)),"Optimize","Cut or rework")))
A18: C13 | B18: Social - Short Video Test | C18: Paid Social | D18: 0 | E18: 0 | F18: 0 | G18: 0 | H18: 0 | I18: 0 | J18: 0 | K18: 0 | L18: 0 | M18: Not yet | N18: 20852.46 | O18: =IF(E18=0,"",F18/E18) | P18: =IF(F18=0,"",D18/F18) | Q18: =IF(F18=0,"",G18/F18) | R18: =IF(G18=0,"",D18/G18) | S18: =IF(G18=0,"",H18/G18) | T18: =IF(G18=0,"",I18/G18) | U18: =IF(I18=0,"",D18/I18) | V18: =IF(I18=0,"",L18/I18) | W18: =IF(D18=0,"",K18/D18) | X18: =IF(D18=0,"",(L18-D18)/D18) | Y18: =IF(OR(U18="",V18=""),"",V18/U18) | Z18: =IF(OR(G18<MinSignups,X18=""),"Too early to judge",IF(X18>=ScaleROI,"Scale",IF(OR(X18>=CutROI,ISNUMBER(M18)),"Optimize","Cut or rework")))
B19: Total | D19: =SUM(D6:D18) | E19: =SUM(E6:E18) | F19: =SUM(F6:F18) | G19: =SUM(G6:G18) | H19: =SUM(H6:H18) | I19: =SUM(I6:I18) | J19: =SUM(J6:J18) | K19: =SUM(K6:K18) | L19: =SUM(L6:L18) | N19: =SUM(N6:N18) | O19: =IF(E19=0,"",F19/E19) | P19: =IF(F19=0,"",D19/F19) | Q19: =IF(F19=0,"",G19/F19) | R19: =IF(G19=0,"",D19/G19) | S19: =IF(G19=0,"",H19/G19) | T19: =IF(G19=0,"",I19/G19) | U19: =IF(I19=0,"",D19/I19) | V19: =IF(I19=0,"",L19/I19) | W19: =IF(D19=0,"",K19/D19) | X19: =IF(D19=0,"",(L19-D19)/D19) | Y19: =IF(OR(U19="",V19=""),"",V19/U19)

Sheet Cohort Conversion
A1: Cohort conversion
A2: Each row is the month people signed up. Columns show how many had made a first purchase within 30, 60, ... 360 days. A cell stays blank until every member of the cohort has had that long.
A4: Customers who had bought (cumulative count)
A5: Sign-up month | B5: Sign-ups | C5: 30 days | D5: 60 days | E5: 90 days | F5: 120 days | G5: 150 days | H5: 180 days | I5: 210 days | J5: 240 days | K5: 270 days | L5: 300 days | M5: 330 days | N5: 360 days
A6: 45292 | B6: 3012 | C6: 730 | D6: 761 | E6: 766 | F6: 767 | G6: 767 | H6: 767 | I6: 767 | J6: 767 | K6: 767 | L6: 767 | M6: 767 | N6: 767
A7: 45323 | B7: 2888 | C7: 755 | D7: 779 | E7: 784 | F7: 784 | G7: 785 | H7: 785 | I7: 785 | J7: 785 | K7: 785 | L7: 785 | M7: 785 | N7: 785
A8: 45352 | B8: 3779 | C8: 956 | D8: 1001 | E8: 1010 | F8: 1011 | G8: 1011 | H8: 1011 | I8: 1011 | J8: 1011 | K8: 1011 | L8: 1011 | M8: 1011 | N8: 1011
A9: 45383 | B9: 3671 | C9: 944 | D9: 1000 | E9: 1005 | F9: 1005 | G9: 1005 | H9: 1005 | I9: 1006 | J9: 1006 | K9: 1006 | L9: 1006 | M9: 1006 | N9: 1006
A10: 45413 | B10: 4015 | C10: 1010 | D10: 1052 | E10: 1063 | F10: 1065 | G10: 1066 | H10: 1066 | I10: 1066 | J10: 1066 | K10: 1066 | L10: 1066 | M10: 1066 | N10: 1066
A11: 45444 | B11: 3882 | C11: 944 | D11: 997 | E11: 1004 | F11: 1006 | G11: 1006 | H11: 1006 | I11: 1006 | J11: 1006 | K11: 1006 | L11: 1006 | M11: 1006 | N11: 1006
A12: 45474 | B12: 4001 | C12: 1018 | D12: 1077 | E12: 1087 | F12: 1087 | G12: 1087 | H12: 1087 | I12: 1087 | J12: 1087 | K12: 1087 | L12: 1087 | M12: 1087 | N12: 1087
A13: 45505 | B13: 4206 | C13: 1025 | D13: 1070 | E13: 1078 | F13: 1080 | G13: 1080 | H13: 1080 | I13: 1080 | J13: 1080 | K13: 1080 | L13: 1080 | M13: 1080 | N13: 1080
A14: 45536 | B14: 4316 | C14: 1060 | D14: 1111 | E14: 1121 | F14: 1124 | G14: 1124 | H14: 1124 | I14: 1124 | J14: 1124 | K14: 1124 | L14: 1124 | M14: 1124 | N14: 1124
A15: 45566 | B15: 5864 | C15: 1342 | D15: 1414 | E15: 1421 | F15: 1421 | G15: 1422 | H15: 1422 | I15: 1422 | J15: 1422 | K15: 1422 | L15: 1422 | M15: 1422 | N15: 1422
A16: 45597 | B16: 6755 | C16: 1637 | D16: 1728 | E16: 1749 | F16: 1753 | G16: 1753 | H16: 1753 | I16: 1753 | J16: 1753 | K16: 1753 | L16: 1753 | M16: 1753 | N16: 1753
A17: 45627 | B17: 7481 | C17: 1776 | D17: 1869 | E17: 1880 | F17: 1884 | G17: 1884 | H17: 1884 | I17: 1884 | J17: 1884 | K17: 1884 | L17: 1884 | M17: 1884 | N17: 1884
A18: 45658 | B18: 4129 | C18: 986 | D18: 1034 | E18: 1042 | F18: 1043 | G18: 1045 | H18: 1045 | I18: 1045 | J18: 1045 | K18: 1045 | L18: 1045 | M18: 1045
A19: 45689 | B19: 3808 | C19: 898 | D19: 948 | E19: 954 | F19: 956 | G19: 956 | H19: 956 | I19: 956 | J19: 956 | K19: 956 | L19: 956
A20: 45717 | B20: 4627 | C20: 1156 | D20: 1211 | E20: 1227 | F20: 1229 | G20: 1230 | H20: 1230 | I20: 1230 | J20: 1230 | K20: 1230
A21: 45748 | B21: 4652 | C21: 1131 | D21: 1193 | E21: 1201 | F21: 1202 | G21: 1202 | H21: 1202 | I21: 1202 | J21: 1202
A22: 45778 | B22: 5009 | C22: 1199 | D22: 1271 | E22: 1283 | F22: 1286 | G22: 1286 | H22: 1286 | I22: 1286
A23: 45809 | B23: 4490 | C23: 1119 | D23: 1167 | E23: 1175 | F23: 1176 | G23: 1176 | H23: 1176
A24: 45839 | B24: 4404 | C24: 1097 | D24: 1149 | E24: 1156 | F24: 1156 | G24: 1156
A25: 45870 | B25: 4491 | C25: 1061 | D25: 1111 | E25: 1122 | F25: 1123
A26: 45901 | B26: 4976 | C26: 1197 | D26: 1250 | E26: 1257
A27: 45931 | B27: 6805 | C27: 1529 | D27: 1611
A28: 45962 | B28: 7740 | C28: 1720
A29: 45992 | B29: 8556
A32: Conversion rate (cumulative % of sign-ups who had bought)
A33: Sign-up month | B33: Sign-ups | C33: 30 days | D33: 60 days | E33: 90 days | F33: 120 days | G33: 150 days | H33: 180 days | I33: 210 days | J33: 240 days | K33: 270 days | L33: 300 days | M33: 330 days | N33: 360 days
A34: =A6 | B34: =B6 | C34: =IF(C6="","",C6/$B6) | D34: =IF(D6="","",D6/$B6) | E34: =IF(E6="","",E6/$B6) | F34: =IF(F6="","",F6/$B6) | G34: =IF(G6="","",G6/$B6) | H34: =IF(H6="","",H6/$B6) | I34: =IF(I6="","",I6/$B6) | J34: =IF(J6="","",J6/$B6) | ... N34: =IF(N6="","",N6/$B6)
A35: =A7 | B35: =B7 | C35: =IF(C7="","",C7/$B7) | D35: =IF(D7="","",D7/$B7) | E35: =IF(E7="","",E7/$B7) | F35: =IF(F7="","",F7/$B7) | G35: =IF(G7="","",G7/$B7) | H35: =IF(H7="","",H7/$B7) | I35: =IF(I7="","",I7/$B7) | J35: =IF(J7="","",J7/$B7) | ... N35: =IF(N7="","",N7/$B7)
A36: =A8 | B36: =B8 | C36: =IF(C8="","",C8/$B8) | D36: =IF(D8="","",D8/$B8) | E36: =IF(E8="","",E8/$B8) | F36: =IF(F8="","",F8/$B8) | G36: =IF(G8="","",G8/$B8) | H36: =IF(H8="","",H8/$B8) | I36: =IF(I8="","",I8/$B8) | J36: =IF(J8="","",J8/$B8) | ... N36: =IF(N8="","",N8/$B8)
A37: =A9 | B37: =B9 | C37: =IF(C9="","",C9/$B9) | D37: =IF(D9="","",D9/$B9) | E37: =IF(E9="","",E9/$B9) | F37: =IF(F9="","",F9/$B9) | G37: =IF(G9="","",G9/$B9) | H37: =IF(H9="","",H9/$B9) | I37: =IF(I9="","",I9/$B9) | J37: =IF(J9="","",J9/$B9) | ... N37: =IF(N9="","",N9/$B9)
A38: =A10 | B38: =B10 | C38: =IF(C10="","",C10/$B10) | D38: =IF(D10="","",D10/$B10) | E38: =IF(E10="","",E10/$B10) | F38: =IF(F10="","",F10/$B10) | G38: =IF(G10="","",G10/$B10) | H38: =IF(H10="","",H10/$B10) | I38: =IF(I10="","",I10/$B10) | J38: =IF(J10="","",J10/$B10) | ... N38: =IF(N10="","",N10/$B10)
A39: =A11 | B39: =B11 | C39: =IF(C11="","",C11/$B11) | D39: =IF(D11="","",D11/$B11) | E39: =IF(E11="","",E11/$B11) | F39: =IF(F11="","",F11/$B11) | G39: =IF(G11="","",G11/$B11) | H39: =IF(H11="","",H11/$B11) | I39: =IF(I11="","",I11/$B11) | J39: =IF(J11="","",J11/$B11) | ... N39: =IF(N11="","",N11/$B11)
A40: =A12 | B40: =B12 | C40: =IF(C12="","",C12/$B12) | D40: =IF(D12="","",D12/$B12) | E40: =IF(E12="","",E12/$B12) | F40: =IF(F12="","",F12/$B12) | G40: =IF(G12="","",G12/$B12) | H40: =IF(H12="","",H12/$B12) | I40: =IF(I12="","",I12/$B12) | J40: =IF(J12="","",J12/$B12) | ... N40: =IF(N12="","",N12/$B12)
A41: =A13 | B41: =B13 | C41: =IF(C13="","",C13/$B13) | D41: =IF(D13="","",D13/$B13) | E41: =IF(E13="","",E13/$B13) | F41: =IF(F13="","",F13/$B13) | G41: =IF(G13="","",G13/$B13) | H41: =IF(H13="","",H13/$B13) | I41: =IF(I13="","",I13/$B13) | J41: =IF(J13="","",J13/$B13) | ... N41: =IF(N13="","",N13/$B13)
A42: =A14 | B42: =B14 | C42: =IF(C14="","",C14/$B14) | D42: =IF(D14="","",D14/$B14) | E42: =IF(E14="","",E14/$B14) | F42: =IF(F14="","",F14/$B14) | G42: =IF(G14="","",G14/$B14) | H42: =IF(H14="","",H14/$B14) | I42: =IF(I14="","",I14/$B14) | J42: =IF(J14="","",J14/$B14) | ... N42: =IF(N14="","",N14/$B14)
A43: =A15 | B43: =B15 | C43: =IF(C15="","",C15/$B15) | D43: =IF(D15="","",D15/$B15) | E43: =IF(E15="","",E15/$B15) | F43: =IF(F15="","",F15/$B15) | G43: =IF(G15="","",G15/$B15) | H43: =IF(H15="","",H15/$B15) | I43: =IF(I15="","",I15/$B15) | J43: =IF(J15="","",J15/$B15) | ... N43: =IF(N15="","",N15/$B15)
...

Sheet Payback
A1: Payback by channel
A2: Cumulative gross profit from a channel's sign-ups ÷ the spend that bought them. 100% means the spend has been earned back. Each column only counts sign-ups with that much history.
A4: Spend on the sign-ups included
A5: Channel | B5: 30 days | C5: 60 days | D5: 90 days | E5: 120 days | F5: 150 days | G5: 180 days | H5: 210 days | I5: 240 days | J5: 270 days | K5: 300 days | L5: 330 days | M5: 360 days
A6: Affiliate | B6: 144420.31 | C6: 136034.05 | D6: 128981.35 | E6: 122082.76 | F6: 115730.91 | G6: 109666.12 | H6: 103258.8 | I6: 96771.77 | J6: 90163.36 | K6: 83862.32 | L6: 78254.51 | M6: 72560.31
A7: Display | B7: 116945.11 | C7: 110070.9 | D7: 104502.69 | E7: 99301.17 | F7: 94210.31 | G7: 89460.18 | H7: 84634.63 | I7: 79363.33 | J7: 74275.41 | K7: 69132.05 | L7: 64554.48 | M7: 60106.44
A8: Email | B8: 41451.99 | C8: 39187.92 | D8: 37233.86 | E8: 35284.76 | F8: 33549.07 | G8: 31833.21 | H8: 30015.79 | I8: 28090.9 | J8: 26306.39 | K8: 24535.56 | L8: 22928.12 | M8: 21407.69
A9: Paid Search | B9: 297101.57 | C9: 283070.63 | D9: 271508.51 | E9: 260690.49 | F9: 250454.59 | G9: 240519 | H9: 227864.14 | I9: 213930.8 | J9: 200541.75 | K9: 187538.42 | L9: 175018.88 | M9: 163159.2
A10: Paid Social | B10: 465727.04 | C10: 416969.84 | D10: 377679.64 | E10: 354484.78 | F10: 338175.67 | G10: 323172.75 | H10: 307963.13 | I10: 291108.26 | J10: 275401.32 | K10: 259358.27 | L10: 244971.23 | M10: 230204.7
A11: Referral | B11: 55874.61 | C11: 52768.4 | D11: 50158.07 | E11: 47593.38 | F11: 45254.92 | G11: 42938.33 | H11: 40508.45 | I11: 38018.95 | J11: 35473.14 | K11: 33064.05 | L11: 30795.95 | M11: 28644.89
A12: Video | B12: 83343.74 | C12: 77316.84 | D12: 72208.41 | E12: 67468.05 | F12: 62753.22 | G12: 58552.13 | H12: 54154.68 | I12: 49570.7 | J12: 45194.18 | K12: 40692.65 | L12: 36868.92 | M12: 33123.3
A15: Cumulative gross profit from those sign-ups
A16: Channel | B16: 30 days | C16: 60 days | D16: 90 days | E16: 120 days | F16: 150 days | G16: 180 days | H16: 210 days | I16: 240 days | J16: 270 days | K16: 300 days | L16: 330 days | M16: 360 days
A17: Affiliate | B17: 122514.65 | C17: 151338.33 | D17: 170239.24 | E17: 178440.74 | F17: 182619.94 | G17: 184052.3 | H17: 180278.49 | I17: 174035.15 | J17: 164921.53 | K17: 153606.89 | L17: 145801.75 | M17: 137551.63
A18: Display | B18: 8499.73 | C18: 11645.87 | D18: 12646.76 | E18: 13051.11 | F18: 12782.6 | G18: 12600.12 | H18: 12243.51 | I18: 11196.92 | J18: 10701.49 | K18: 10083.56 | L18: 9063.36 | M18: 8672.26
A19: Email | B19: 28943.05 | C19: 35296.07 | D19: 38797.89 | E19: 40243.06 | F19: 40618.71 | G19: 39874.85 | H19: 39281.84 | I19: 37606.87 | J19: 36163.22 | K19: 34760.19 | L19: 33133.12 | M19: 31323.3
A20: Paid Search | B20: 191993.82 | C20: 243374.36 | D20: 274743.28 | E20: 292543.84 | F20: 303288.39 | G20: 308060.52 | H20: 305114.36 | I20: 294116.57 | J20: 282675.84 | K20: 268056.71 | L20: 255775.23 | M20: 241744.54
A21: Paid Social | B21: 169477.71 | C21: 204352.97 | D21: 215910.95 | E21: 223675.28 | F21: 227723.51 | G21: 227659.3 | H21: 224401.56 | I21: 217004.78 | J21: 209622.35 | K21: 201228.41 | L21: 192771.81 | M21: 183628.34
A22: Referral | B22: 47176.51 | C22: 61425.95 | D22: 71078.98 | E22: 77283.69 | F22: 79647.62 | G22: 78048.33 | H22: 77500.64 | I22: 75616.67 | J22: 72757.02 | K22: 70102.82 | L22: 66628.94 | M22: 64259.26
A23: Video | B23: 40881.44 | C23: 50581.89 | D23: 55887.49 | E23: 58399.12 | F23: 59210.15 | G23: 58837.6 | H23: 57718.75 | I23: 53354.5 | J23: 49897.66 | K23: 45121.88 | L23: 41147.57 | M23: 38325.55
A26: Payback ratio (gross profit ÷ spend)
A27: Channel | B27: 30 days | C27: 60 days | D27: 90 days | E27: 120 days | F27: 150 days | G27: 180 days | H27: 210 days | I27: 240 days | J27: 270 days | K27: 300 days | L27: 330 days | M27: 360 days | N27: Pays back within
A28: Affiliate | B28: =IF(OR(B6="",B6=0),"",B17/B6) | C28: =IF(OR(C6="",C6=0),"",C17/C6) | D28: =IF(OR(D6="",D6=0),"",D17/D6) | E28: =IF(OR(E6="",E6=0),"",E17/E6) | F28: =IF(OR(F6="",F6=0),"",F17/F6) | G28: =IF(OR(G6="",G6=0),"",G17/G6) | H28: =IF(OR(H6="",H6=0),"",H17/H6) | I28: =IF(OR(I6="",I6=0),"",I17/I6) | ... M28: =IF(OR(M6="",M6=0),"",M17/M6) | N28: =IFERROR(INDEX($B$27:$M$27,MATCH(1,B41:M41,0)),"Not within 12 months")
A29: Display | B29: =IF(OR(B7="",B7=0),"",B18/B7) | C29: =IF(OR(C7="",C7=0),"",C18/C7) | D29: =IF(OR(D7="",D7=0),"",D18/D7) | E29: =IF(OR(E7="",E7=0),"",E18/E7) | F29: =IF(OR(F7="",F7=0),"",F18/F7) | G29: =IF(OR(G7="",G7=0),"",G18/G7) | H29: =IF(OR(H7="",H7=0),"",H18/H7) | I29: =IF(OR(I7="",I7=0),"",I18/I7) | ... M29: =IF(OR(M7="",M7=0),"",M18/M7) | N29: =IFERROR(INDEX($B$27:$M$27,MATCH(1,B42:M42,0)),"Not within 12 months")
A30: Email | B30: =IF(OR(B8="",B8=0),"",B19/B8) | C30: =IF(OR(C8="",C8=0),"",C19/C8) | D30: =IF(OR(D8="",D8=0),"",D19/D8) | E30: =IF(OR(E8="",E8=0),"",E19/E8) | F30: =IF(OR(F8="",F8=0),"",F19/F8) | G30: =IF(OR(G8="",G8=0),"",G19/G8) | H30: =IF(OR(H8="",H8=0),"",H19/H8) | I30: =IF(OR(I8="",I8=0),"",I19/I8) | ... M30: =IF(OR(M8="",M8=0),"",M19/M8) | N30: =IFERROR(INDEX($B$27:$M$27,MATCH(1,B43:M43,0)),"Not within 12 months")
A31: Paid Search | B31: =IF(OR(B9="",B9=0),"",B20/B9) | C31: =IF(OR(C9="",C9=0),"",C20/C9) | D31: =IF(OR(D9="",D9=0),"",D20/D9) | E31: =IF(OR(E9="",E9=0),"",E20/E9) | F31: =IF(OR(F9="",F9=0),"",F20/F9) | G31: =IF(OR(G9="",G9=0),"",G20/G9) | H31: =IF(OR(H9="",H9=0),"",H20/H9) | I31: =IF(OR(I9="",I9=0),"",I20/I9) | ... M31: =IF(OR(M9="",M9=0),"",M20/M9) | N31: =IFERROR(INDEX($B$27:$M$27,MATCH(1,B44:M44,0)),"Not within 12 months")
A32: Paid Social | B32: =IF(OR(B10="",B10=0),"",B21/B10) | C32: =IF(OR(C10="",C10=0),"",C21/C10) | D32: =IF(OR(D10="",D10=0),"",D21/D10) | E32: =IF(OR(E10="",E10=0),"",E21/E10) | F32: =IF(OR(F10="",F10=0),"",F21/F10) | G32: =IF(OR(G10="",G10=0),"",G21/G10) | H32: =IF(OR(H10="",H10=0),"",H21/H10) | I32: =IF(OR(I10="",I10=0),"",I21/I10) | ... M32: =IF(OR(M10="",M10=0),"",M21/M10) | N32: =IFERROR(INDEX($B$27:$M$27,MATCH(1,B45:M45,0)),"Not within 12 months")
A33: Referral | B33: =IF(OR(B11="",B11=0),"",B22/B11) | C33: =IF(OR(C11="",C11=0),"",C22/C11) | D33: =IF(OR(D11="",D11=0),"",D22/D11) | E33: =IF(OR(E11="",E11=0),"",E22/E11) | F33: =IF(OR(F11="",F11=0),"",F22/F11) | G33: =IF(OR(G11="",G11=0),"",G22/G11) | H33: =IF(OR(H11="",H11=0),"",H22/H11) | I33: =IF(OR(I11="",I11=0),"",I22/I11) | ... M33: =IF(OR(M11="",M11=0),"",M22/M11) | N33: =IFERROR(INDEX($B$27:$M$27,MATCH(1,B46:M46,0)),"Not within 12 months")
A34: Video | B34: =IF(OR(B12="",B12=0),"",B23/B12) | C34: =IF(OR(C12="",C12=0),"",C23/C12) | D34: =IF(OR(D12="",D12=0),"",D23/D12) | E34: =IF(OR(E12="",E12=0),"",E23/E12) | F34: =IF(OR(F12="",F12=0),"",F23/F12) | G34: =IF(OR(G12="",G12=0),"",G23/G12) | H34: =IF(OR(H12="",H12=0),"",H23/H12) | I34: =IF(OR(I12="",I12=0),"",I23/I12) | ... M34: =IF(OR(M12="",M12=0),"",M23/M12) | N34: =IFERROR(INDEX($B$27:$M$27,MATCH(1,B47:M47,0)),"Not within 12 months")
A35: Break-even | B35: 1 | C35: 1 | D35: 1 | E35: 1 | F35: 1 | G35: 1 | H35: 1 | I35: 1 | J35: 1 | K35: 1 | L35: 1 | M35: 1
A39: Helper: 1 once the channel has paid back (feeds 'Pays back within')
A40: Channel | B40: 30 days | C40: 60 days | D40: 90 days | E40: 120 days | F40: 150 days | G40: 180 days | H40: 210 days | I40: 240 days | J40: 270 days | K40: 300 days | L40: 330 days | M40: 360 days
A41: Affiliate | B41: =IF(AND(ISNUMBER(B28),B28>=1),1,0) | C41: =IF(AND(ISNUMBER(C28),C28>=1),1,0) | D41: =IF(AND(ISNUMBER(D28),D28>=1),1,0) | E41: =IF(AND(ISNUMBER(E28),E28>=1),1,0) | F41: =IF(AND(ISNUMBER(F28),F28>=1),1,0) | G41: =IF(AND(ISNUMBER(G28),G28>=1),1,0) | H41: =IF(AND(ISNUMBER(H28),H28>=1),1,0) | I41: =IF(AND(ISNUMBER(I28),I28>=1),1,0) | ... M41: =IF(AND(ISNUMBER(M28),M28>=1),1,0)
A42: Display | B42: =IF(AND(ISNUMBER(B29),B29>=1),1,0) | C42: =IF(AND(ISNUMBER(C29),C29>=1),1,0) | D42: =IF(AND(ISNUMBER(D29),D29>=1),1,0) | E42: =IF(AND(ISNUMBER(E29),E29>=1),1,0) | F42: =IF(AND(ISNUMBER(F29),F29>=1),1,0) | G42: =IF(AND(ISNUMBER(G29),G29>=1),1,0) | H42: =IF(AND(ISNUMBER(H29),H29>=1),1,0) | I42: =IF(AND(ISNUMBER(I29),I29>=1),1,0) | ... M42: =IF(AND(ISNUMBER(M29),M29>=1),1,0)
A43: Email | B43: =IF(AND(ISNUMBER(B30),B30>=1),1,0) | C43: =IF(AND(ISNUMBER(C30),C30>=1),1,0) | D43: =IF(AND(ISNUMBER(D30),D30>=1),1,0) | E43: =IF(AND(ISNUMBER(E30),E30>=1),1,0) | F43: =IF(AND(ISNUMBER(F30),F30>=1),1,0) | G43: =IF(AND(ISNUMBER(G30),G30>=1),1,0) | H43: =IF(AND(ISNUMBER(H30),H30>=1),1,0) | I43: =IF(AND(ISNUMBER(I30),I30>=1),1,0) | ... M43: =IF(AND(ISNUMBER(M30),M30>=1),1,0)
A44: Paid Search | B44: =IF(AND(ISNUMBER(B31),B31>=1),1,0) | C44: =IF(AND(ISNUMBER(C31),C31>=1),1,0) | D44: =IF(AND(ISNUMBER(D31),D31>=1),1,0) | E44: =IF(AND(ISNUMBER(E31),E31>=1),1,0) | F44: =IF(AND(ISNUMBER(F31),F31>=1),1,0) | G44: =IF(AND(ISNUMBER(G31),G31>=1),1,0) | H44: =IF(AND(ISNUMBER(H31),H31>=1),1,0) | I44: =IF(AND(ISNUMBER(I31),I31>=1),1,0) | ... M44: =IF(AND(ISNUMBER(M31),M31>=1),1,0)
A45: Paid Social | B45: =IF(AND(ISNUMBER(B32),B32>=1),1,0) | C45: =IF(AND(ISNUMBER(C32),C32>=1),1,0) | D45: =IF(AND(ISNUMBER(D32),D32>=1),1,0) | E45: =IF(AND(ISNUMBER(E32),E32>=1),1,0) | F45: =IF(AND(ISNUMBER(F32),F32>=1),1,0) | G45: =IF(AND(ISNUMBER(G32),G32>=1),1,0) | H45: =IF(AND(ISNUMBER(H32),H32>=1),1,0) | I45: =IF(AND(ISNUMBER(I32),I32>=1),1,0) | ... M45: =IF(AND(ISNUMBER(M32),M32>=1),1,0)
A46: Referral | B46: =IF(AND(ISNUMBER(B33),B33>=1),1,0) | C46: =IF(AND(ISNUMBER(C33),C33>=1),1,0) | D46: =IF(AND(ISNUMBER(D33),D33>=1),1,0) | E46: =IF(AND(ISNUMBER(E33),E33>=1),1,0) | F46: =IF(AND(ISNUMBER(F33),F33>=1),1,0) | G46: =IF(AND(ISNUMBER(G33),G33>=1),1,0) | H46: =IF(AND(ISNUMBER(H33),H33>=1),1,0) | I46: =IF(AND(ISNUMBER(I33),I33>=1),1,0) | ... M46: =IF(AND(ISNUMBER(M33),M33>=1),1,0)
A47: Video | B47: =IF(AND(ISNUMBER(B34),B34>=1),1,0) | C47: =IF(AND(ISNUMBER(C34),C34>=1),1,0) | D47: =IF(AND(ISNUMBER(D34),D34>=1),1,0) | E47: =IF(AND(ISNUMBER(E34),E34>=1),1,0) | F47: =IF(AND(ISNUMBER(F34),F34>=1),1,0) | G47: =IF(AND(ISNUMBER(G34),G34>=1),1,0) | H47: =IF(AND(ISNUMBER(H34),H34>=1),1,0) | I47: =IF(AND(ISNUMBER(I34),I34>=1),1,0) | ... M47: =IF(AND(ISNUMBER(M34),M34>=1),1,0)

Sheet Budget Scenario
A1: Budget scenario
A2: Change the yellow cells to test budget moves. Projections use each campaign's CAC and gross profit per customer from the Scorecard, over a year of spend.
A4: Campaign | B4: Channel | C4: Action | D4: Spend, last 12 months | E4: Change in spend | F4: Scenario spend | G4: CAC | H4: Gross profit per customer | I4: Customers a year (now) | J4: Customers a year (scenario) | K4: 180-day gross profit (now) | L4: 180-day gross profit (scenario) | M4: Gross profit after spend: change
A5: =Scorecard!B6 | B5: =Scorecard!C6 | C5: =Scorecard!Z6 | D5: =Scorecard!N6 | E5: 0.5 | F5: =D5*(1+E5) | G5: =Scorecard!U6 | H5: =Scorecard!V6 | I5: =IF(G5="","",D5/G5) | J5: =IF(G5="","",F5/G5) | K5: =IF(I5="","",I5*H5) | L5: =IF(J5="","",J5*H5) | M5: =IF(OR(K5="",L5=""),"",(L5-F5)-(K5-D5))
A6: =Scorecard!B7 | B6: =Scorecard!C7 | C6: =Scorecard!Z7 | D6: =Scorecard!N7 | E6: 0.5 | F6: =D6*(1+E6) | G6: =Scorecard!U7 | H6: =Scorecard!V7 | I6: =IF(G6="","",D6/G6) | J6: =IF(G6="","",F6/G6) | K6: =IF(I6="","",I6*H6) | L6: =IF(J6="","",J6*H6) | M6: =IF(OR(K6="",L6=""),"",(L6-F6)-(K6-D6))
A7: =Scorecard!B8 | B7: =Scorecard!C8 | C7: =Scorecard!Z8 | D7: =Scorecard!N8 | E7: 0.5 | F7: =D7*(1+E7) | G7: =Scorecard!U8 | H7: =Scorecard!V8 | I7: =IF(G7="","",D7/G7) | J7: =IF(G7="","",F7/G7) | K7: =IF(I7="","",I7*H7) | L7: =IF(J7="","",J7*H7) | M7: =IF(OR(K7="",L7=""),"",(L7-F7)-(K7-D7))
A8: =Scorecard!B9 | B8: =Scorecard!C9 | C8: =Scorecard!Z9 | D8: =Scorecard!N9 | E8: 0.5 | F8: =D8*(1+E8) | G8: =Scorecard!U9 | H8: =Scorecard!V9 | I8: =IF(G8="","",D8/G8) | J8: =IF(G8="","",F8/G8) | K8: =IF(I8="","",I8*H8) | L8: =IF(J8="","",J8*H8) | M8: =IF(OR(K8="",L8=""),"",(L8-F8)-(K8-D8))
A9: =Scorecard!B10 | B9: =Scorecard!C10 | C9: =Scorecard!Z10 | D9: =Scorecard!N10 | E9: 0 | F9: =D9*(1+E9) | G9: =Scorecard!U10 | H9: =Scorecard!V10 | I9: =IF(G9="","",D9/G9) | J9: =IF(G9="","",F9/G9) | K9: =IF(I9="","",I9*H9) | L9: =IF(J9="","",J9*H9) | M9: =IF(OR(K9="",L9=""),"",(L9-F9)-(K9-D9))
A10: =Scorecard!B11 | B10: =Scorecard!C11 | C10: =Scorecard!Z11 | D10: =Scorecard!N11 | E10: 0 | F10: =D10*(1+E10) | G10: =Scorecard!U11 | H10: =Scorecard!V11 | I10: =IF(G10="","",D10/G10) | J10: =IF(G10="","",F10/G10) | K10: =IF(I10="","",I10*H10) | L10: =IF(J10="","",J10*H10) | M10: =IF(OR(K10="",L10=""),"",(L10-F10)-(K10-D10))
A11: =Scorecard!B12 | B11: =Scorecard!C12 | C11: =Scorecard!Z12 | D11: =Scorecard!N12 | E11: 0 | F11: =D11*(1+E11) | G11: =Scorecard!U12 | H11: =Scorecard!V12 | I11: =IF(G11="","",D11/G11) | J11: =IF(G11="","",F11/G11) | K11: =IF(I11="","",I11*H11) | L11: =IF(J11="","",J11*H11) | M11: =IF(OR(K11="",L11=""),"",(L11-F11)-(K11-D11))
A12: =Scorecard!B13 | B12: =Scorecard!C13 | C12: =Scorecard!Z13 | D12: =Scorecard!N13 | E12: 0 | F12: =D12*(1+E12) | G12: =Scorecard!U13 | H12: =Scorecard!V13 | I12: =IF(G12="","",D12/G12) | J12: =IF(G12="","",F12/G12) | K12: =IF(I12="","",I12*H12) | L12: =IF(J12="","",J12*H12) | M12: =IF(OR(K12="",L12=""),"",(L12-F12)-(K12-D12))
A13: =Scorecard!B14 | B13: =Scorecard!C14 | C13: =Scorecard!Z14 | D13: =Scorecard!N14 | E13: -0.5 | F13: =D13*(1+E13) | G13: =Scorecard!U14 | H13: =Scorecard!V14 | I13: =IF(G13="","",D13/G13) | J13: =IF(G13="","",F13/G13) | K13: =IF(I13="","",I13*H13) | L13: =IF(J13="","",J13*H13) | M13: =IF(OR(K13="",L13=""),"",(L13-F13)-(K13-D13))
A14: =Scorecard!B15 | B14: =Scorecard!C15 | C14: =Scorecard!Z15 | D14: =Scorecard!N15 | E14: -0.5 | F14: =D14*(1+E14) | G14: =Scorecard!U15 | H14: =Scorecard!V15 | I14: =IF(G14="","",D14/G14) | J14: =IF(G14="","",F14/G14) | K14: =IF(I14="","",I14*H14) | L14: =IF(J14="","",J14*H14) | M14: =IF(OR(K14="",L14=""),"",(L14-F14)-(K14-D14))
A15: =Scorecard!B16 | B15: =Scorecard!C16 | C15: =Scorecard!Z16 | D15: =Scorecard!N16 | E15: -0.5 | F15: =D15*(1+E15) | G15: =Scorecard!U16 | H15: =Scorecard!V16 | I15: =IF(G15="","",D15/G15) | J15: =IF(G15="","",F15/G15) | K15: =IF(I15="","",I15*H15) | L15: =IF(J15="","",J15*H15) | M15: =IF(OR(K15="",L15=""),"",(L15-F15)-(K15-D15))
A16: =Scorecard!B17 | B16: =Scorecard!C17 | C16: =Scorecard!Z17 | D16: =Scorecard!N17 | E16: -0.5 | F16: =D16*(1+E16) | G16: =Scorecard!U17 | H16: =Scorecard!V17 | I16: =IF(G16="","",D16/G16) | J16: =IF(G16="","",F16/G16) | K16: =IF(I16="","",I16*H16) | L16: =IF(J16="","",J16*H16) | M16: =IF(OR(K16="",L16=""),"",(L16-F16)-(K16-D16))
A17: =Scorecard!B18 | B17: =Scorecard!C18 | C17: =Scorecard!Z18 | D17: =Scorecard!N18 | E17: 0 | F17: =D17*(1+E17) | G17: =Scorecard!U18 | H17: =Scorecard!V18 | I17: =IF(G17="","",D17/G17) | J17: =IF(G17="","",F17/G17) | K17: =IF(I17="","",I17*H17) | L17: =IF(J17="","",J17*H17) | M17: =IF(OR(K17="",L17=""),"",(L17-F17)-(K17-D17))
A18: Total | D18: =SUM(D5:D17) | F18: =SUM(F5:F17) | I18: =SUM(I5:I17) | J18: =SUM(J5:J17) | K18: =SUM(K5:K17) | L18: =SUM(L5:L17) | M18: =SUM(M5:M17)
A20: What the scenario does
A21: Change in annual spend | D21: =F18-D18
A22: Extra customers a year | D22: =J18-I18
A23: Extra 180-day gross profit | D23: =L18-K18
A24: Gross profit after spend: change | D24: =M18
A26: Assumes CAC and gross profit per customer stay the same as budgets change. In practice CAC usually rises as a campaign scales (smaller audiences, higher bids), so treat increases as an upper bound and test them in steps. Defaults: halve campaigns marked 'Cut or rework', grow those marked 'Scale' by 50%.

Sheet Channel Monthly
A1: Monthly trend by channel
A2: Spend and first purchases by calendar month. Monthly CAC here is operational: a month's spend divided by that month's first purchases, some from people who signed up earlier.
A4: Spend
A5: Month | B5: Affiliate | C5: Display | D5: Email | E5: Paid Search | F5: Paid Social | G5: Referral | H5: Video | I5: Total
A6: 45292 | B6: 2928.99 | C6: 4344.44 | D6: 1534.15 | E6: 11291.36 | F6: 11838.84 | G6: 2102.37 | I6: =SUM(B6:H6)
A7: 45323 | B7: 2741.82 | C7: 4049.62 | D7: 1413.03 | E7: 10862.98 | F7: 10699.3 | G7: 1940.33 | I7: =SUM(B7:H7)
A8: 45352 | B8: 6201.6 | C8: 4890.79 | D8: 1690.78 | E8: 12365.32 | F8: 13272.59 | G8: 2268.37 | I8: =SUM(B8:H8)
A9: 45383 | B9: 5932.86 | C9: 4777.17 | D9: 1627.24 | E9: 12609.64 | F9: 12754.15 | G9: 2286.2 | I9: =SUM(B9:H9)
A10: 45413 | B10: 6584.06 | C10: 4858.62 | D10: 1728.04 | E10: 13292.24 | F10: 13659.27 | G10: 2315.37 | I10: =SUM(B10:H10)
A11: 45444 | B11: 5829.11 | C11: 4406.99 | D11: 1643.69 | E11: 12100.27 | F11: 12645.73 | G11: 2128.04 | H11: 3892.08 | I11: =SUM(B11:H11)
A12: 45474 | B12: 5740.29 | C12: 4566.83 | D12: 1605.07 | E12: 12273.75 | F12: 12589.9 | G12: 2155.84 | H12: 4143.67 | I12: =SUM(B12:H12)
A13: 45505 | B13: 6093.45 | C13: 4535.09 | D13: 1736.78 | E13: 12947.39 | F13: 13325.55 | G13: 2234.79 | H13: 4010.69 | I13: =SUM(B13:H13)
A14: 45536 | B14: 6074.91 | C14: 4966.35 | D14: 1772.67 | E14: 12907.84 | F14: 13799.19 | G14: 2296.23 | H14: 4381.71 | I14: =SUM(B14:H14)
A15: 45566 | B15: 6928.62 | C15: 5091.62 | D15: 1892.99 | E15: 14377.32 | F15: 32823.72 | G15: 2565.77 | H15: 4755.45 | I15: =SUM(B15:H15)
A16: 45597 | B16: 7697.91 | C16: 5868.76 | D16: 2118.71 | E16: 17305.16 | F16: 37037.87 | G16: 2840.68 | H16: 5086.61 | I16: =SUM(B16:H16)
A17: 45627 | B17: 8650.71 | C17: 6787.95 | D17: 2330 | E17: 18447.17 | F17: 42951.12 | G17: 3099.75 | H17: 6080.7 | I17: =SUM(B17:H17)
A18: 45658 | B18: 5961.02 | C18: 4663.69 | D18: 1567.95 | E18: 12297.66 | F18: 15197.34 | G18: 2221.21 | H18: 3906.05 | I18: =SUM(B18:H18)
A19: 45689 | B19: 5031.84 | C19: 4132.93 | D19: 1443.33 | E19: 11207.93 | F19: 13313.36 | G19: 2090.52 | H19: 3462.8 | I19: =SUM(B19:H19)
A20: 45717 | B20: 6498.77 | C20: 5321.24 | D20: 1813.98 | E20: 13659.49 | F20: 16096.24 | G20: 2464.58 | H20: 4545.47 | I20: =SUM(B20:H20)
A21: 45748 | B21: 6437.34 | C21: 5021.37 | D21: 1772.3 | E21: 13213.35 | F21: 16072.47 | G21: 2525.77 | H21: 4337.08 | I21: =SUM(B21:H21)
A22: 45778 | B22: 6842.35 | C22: 5475.75 | D22: 2014.31 | E22: 14497.44 | F22: 17132.05 | G22: 2582.23 | H22: 4765.42 | I22: =SUM(B22:H22)
... A29: 45992 | B29: 9271.13 | C29: 7122.08 | D29: 2637.29 | E29: 14931.88 | F29: 53669.61 | G29: 3451.85 | H29: 6277.07 | I29: =SUM(B29:H29)
A32: First purchases (new customers)
A33: Month | B33: Affiliate | C33: Display | D33: Email | E33: Paid Search | F33: Paid Social | G33: Referral | H33: Video | I33: Total
A34: 45292 | B34: 203 | C34: 11 | D34: 27 | E34: 168 | F34: 130 | G34: 40 | I34: =SUM(B34:H34)
A35: 45323 | B35: 250 | C35: 14 | D35: 44 | E35: 211 | F35: 186 | G35: 54 | I35: =SUM(B35:H35)
A36: 45352 | B36: 380 | C36: 36 | D36: 27 | E36: 245 | F36: 227 | G36: 55 | I36: =SUM(B36:H36)
A37: 45383 | B37: 386 | C37: 22 | D37: 42 | E37: 233 | F37: 222 | G37: 60 | I37: =SUM(B37:H37)
A38: 45413 | B38: 437 | C38: 22 | D38: 42 | E38: 272 | F38: 252 | G38: 63 | I38: =SUM(B38:H38)
A39: 45444 | B39: 362 | C39: 19 | D39: 42 | E39: 247 | F39: 235 | G39: 51 | H39: 43 | I39: =SUM(B39:H39)
A40: 45474 | B40: 386 | C40: 25 | D40: 41 | E40: 258 | F40: 229 | G40: 54 | H40: 72 | I40: =SUM(B40:H40)
A41: 45505 | B41: 375 | C41: 29 | D41: 47 | E41: 273 | F41: 251 | G41: 51 | H41: 76 | I41: =SUM(B41:H41)
A42: 45536 | B42: 384 | C42: 22 | D42: 42 | E42: 281 | F42: 228 | G42: 53 | H42: 65 | I42: =SUM(B42:H42)
A43: 45566 | B43: 431 | C43: 23 | D43: 66 | E43: 283 | F43: 388 | G43: 61 | H43: 83 | I43: =SUM(B43:H43)
A44: 45597 | B44: 495 | C44: 27 | D44: 62 | E44: 363 | F44: 522 | G44: 79 | H44: 90 | I44: =SUM(B44:H44)
A45: 45627 | B45: 577 | C45: 32 | D45: 69 | E45: 390 | F45: 605 | G45: 73 | H45: 101 | I45: =SUM(B45:H45)
A46: 45658 | B46: 414 | C46: 42 | D46: 46 | E46: 275 | F46: 403 | G46: 55 | H46: 74 | I46: =SUM(B46:H46)
A47: 45689 | B47: 333 | C47: 24 | D47: 39 | E47: 248 | F47: 198 | G47: 59 | H47: 58 | I47: =SUM(B47:H47)
A48: 45717 | B48: 438 | C48: 35 | D48: 44 | E48: 288 | F48: 254 | G48: 57 | H48: 81 | I48: =SUM(B48:H48)
A49: 45748 | B49: 443 | C49: 30 | D49: 44 | E49: 304 | F49: 242 | G49: 54 | H49: 73 | I49: =SUM(B49:H49)
...

Sheet Data Checks
A1: Data quality checks
A2: Run on the staging tables before any analysis. Every check should pass.
A4: Check | B4: Failing rows | C4: Result
A5: Sign-ups with an unknown campaign | B5: 0 | C5: =IF(B5=0,"Pass","Fail")
A6: Spend rows with an unknown campaign | B6: 0 | C6: =IF(B6=0,"Pass","Fail")
A7: Spend outside the campaign dates | B7: 0 | C7: =IF(B7=0,"Pass","Fail")
A8: Orders from an unknown user | B8: 0 | C8: =IF(B8=0,"Pass","Fail")
A9: Orders dated before the sign-up | B9: 0 | C9: =IF(B9=0,"Pass","Fail")
A10: Duplicate user IDs | B10: 0 | C10: =IF(B10=0,"Pass","Fail")
A11: Duplicate order IDs | B11: 0 | C11: =IF(B11=0,"Pass","Fail")
A12: Negative spend, revenue or cost | B12: 0 | C12: =IF(B12=0,"Pass","Fail")
A13: Missing dates or amounts | B13: 0 | C13: =IF(B13=0,"Pass","Fail")

Sheet Definitions
A1: Definitions and run details
A3: Term | B3: Definition
A4: Sign-up | B4: A person who registered, credited to the campaign that brought them (first-touch attribution).
A5: Customer | B5: A sign-up who made a first purchase within 180 days of signing up.
A6: Measured window | B6: Sign-ups on or before the mature cutoff, so each has a full 180 days of history. Spend is counted over the same dates.
A7: Cohort | B7: Everyone who signed up in the same calendar month.
A8: Cohort conversion | B8: Share of a cohort that had bought within 30, 60, ... 360 days. Blank until every member has had that long.
A9: CAC | B9: Customer acquisition cost: spend ÷ customers acquired within 180 days.
A10: ROAS | B10: Return on ad spend: 180-day revenue ÷ spend.
A11: ROI | B11: (180-day gross profit − spend) ÷ spend. Uses gross profit, not revenue, because revenue ignores the cost of the goods sold.
A12: Payback | B12: The first 30-day period in which cumulative gross profit from a campaign's sign-ups covered the spend that bought them.
A13: LTV:CAC | B13: 180-day gross profit per customer ÷ CAC. Above 1 means a customer is worth more than they cost.
A14: Actions | B14: Scale: ROI at or above the scale threshold. Optimize: ROI between the thresholds, or below the cut threshold but paying back within 12 months. Cut or rework: below the cut threshold and no payback within 12 months. Too early: fewer measured sign-ups than the minimum.
... A22: Built | B22: 2026-10-04 14:07 by mroi v1.0.0
